Workbook
Name CalendarYear: 'Itinerary Calendar'!$F$3
Name CalendarYear: 'Itinerary-CODE'!$K$2
Name ColumnTitleRegion1..H12.1: 'Itinerary Calendar'!$B$11
Name ColumnTitleRegion1..H12.1: #REF!
Name ColumnTitleRegion2..C14.1: 'Itinerary Calendar'!$B$11
Name ColumnTitleRegion2..C14.1: #REF!
Name DaysAndWeeks: {0,1,2,3,4,5,6} + {0;1;2;3;4;5}*7
Name DaysAndWeeks: {0,1,2,3,4,5,6} + {0;1;2;3;4;5}*7
Name DaysAndWeeks1: {0,1,2,3,4,5,6} + {0;1;2;3;4;5}*7
Name DreamStartDate: 'Trip Dreaming'!$E$3
Name DreamStartMonth: 'Itinerary Calendar'!$H$3
Name DreamStartMonth2: 'Itinerary Calendar'!$N$2
Name DreamStartMonth3: 'Itinerary Calendar'!$N$3
Name DreamStartYear: 'Itinerary Calendar'!$G$3
Name RowTitleRegion1..K3: 'Itinerary Calendar'!$J$11
Name RowTitleRegion1..K3: #REF!
Name WeekStart: 'Itinerary Calendar'!#REF!
Name WeekStart: 'Itinerary-CODE'!$K$3
Name WeekStart1: 'Itinerary-CODE'!$H$3

Sheet Directory
A1: Solo Trip Planner Directory
A2: Put together by Hayleley - Your Best Friend for Solo Travel Inspiration

Sheet Dashboard

Sheet Trip Dreaming
B1: Trip Dreaming | J1: Dream Outline
B2: This is the spot to put down all of those places you want to go… and how long you want to stay there. | J2: No need to put anything over here. It will appear magically.
B3: Trip Start Date | E3: 44694 | F3: *double check this PLEASE (MM/DD/YYYY) | J3: Total # of Days | L3: =SUM(D6:D30) -> 53
B5: Stop on Trip | D5: Days in Location | E5: City | F5: Country | G5: Preferred Month | H5: Average Room Cost | J5: Stop | K5: Start Date | L5: End Date | M5: Location | N5: # Days
B6: # | C6: 1 | D6: 3 | E6: Zurich | F6: Switzerland | J6: 1 | K6: =IFERROR(E3," ") -> 44694 | L6: =IFERROR(IF(J6=C6,K6+D6,K6+VLOOKUP(J6,$C$6:$D$30,2,FALSE))," ") -> 44697 | M6: =IFERROR(IF(N6=0," ",IF(J6=C6,CONCATENATE(E6,", ",F6),CONCATENATE(VLOOKUP(J6,$C$6:$F$30,3,FALSE),", ",VLOOKUP(J6,$C$6:$F$30,4,FALSE))))," ") -> Zurich, Switzerland | N6: =IFERROR(VLOOKUP(J6,$C$6:$F$30,2,FALSE)," ") -> 3
B7: # | C7: 2 | D7: 3 | E7: Lucerne | F7: Switzerland | J7: 2 | K7: =IFERROR(IF(N6=0," ",L6)," ") -> 44697 | L7: =IFERROR(IF(J7=C7,K7+D7,K7+VLOOKUP(J7,$C$6:$D$30,2,FALSE))," ") -> 44700 | M7: =IFERROR(IF(N7=0," ",IF(J7=C7,CONCATENATE(E7,", ",F7),CONCATENATE(VLOOKUP(J7,$C$6:$F$30,3,FALSE),", ",VLOOKUP(J7,$C$6:$F$30,4,FALSE))))," ") -> Lucerne, Switzerland | N7: =IFERROR(VLOOKUP(J7,$C$6:$F$30,2,FALSE)," ") -> 3
B8: # | C8: 4 | D8: 7 | E8: Interlaken | F8: Switzerland | J8: 3 | K8: =IFERROR(IF(N7=0," ",L7)," ") -> 44700 | L8: =IFERROR(IF(J8=C8,K8+D8,K8+VLOOKUP(J8,$C$6:$D$30,2,FALSE))," ") -> 44704 | M8: =IFERROR(IF(N8=0," ",IF(J8=C8,CONCATENATE(E8,", ",F8),CONCATENATE(VLOOKUP(J8,$C$6:$F$30,3,FALSE),", ",VLOOKUP(J8,$C$6:$F$30,4,FALSE))))," ") -> Salzburg, Austria | N8: =IFERROR(VLOOKUP(J8,$C$6:$F$30,2,FALSE)," ") -> 4
B9: # | C9: 3 | D9: 4 | E9: Salzburg | F9: Austria | J9: 4 | K9: =IFERROR(IF(N8=0," ",L8)," ") -> 44704 | L9: =IFERROR(IF(J9=C9,K9+D9,K9+VLOOKUP(J9,$C$6:$D$30,2,FALSE))," ") -> 44711 | M9: =IFERROR(IF(N9=0," ",IF(J9=C9,CONCATENATE(E9,", ",F9),CONCATENATE(VLOOKUP(J9,$C$6:$F$30,3,FALSE),", ",VLOOKUP(J9,$C$6:$F$30,4,FALSE))))," ") -> Interlaken, Switzerland | N9: =IFERROR(VLOOKUP(J9,$C$6:$F$30,2,FALSE)," ") -> 7
B10: # | C10: 5 | D10: 1 | E10: Halstatt | F10: Austria | J10: 5 | K10: =IFERROR(IF(N9=0," ",L9)," ") -> 44711 | L10: =IFERROR(IF(J10=C10,K10+D10,K10+VLOOKUP(J10,$C$6:$D$30,2,FALSE))," ") -> 44712 | M10: =IFERROR(IF(N10=0," ",IF(J10=C10,CONCATENATE(E10,", ",F10),CONCATENATE(VLOOKUP(J10,$C$6:$F$30,3,FALSE),", ",VLOOKUP(J10,$C$6:$F$30,4,FALSE))))," ") -> Halstatt, Austria | N10: =IFERROR(VLOOKUP(J10,$C$6:$F$30,2,FALSE)," ") -> 1
B11: # | C11: 6 | D11: 3 | E11: Munich | F11: Germany | J11: 6 | K11: =IFERROR(IF(N10=0," ",L10)," ") -> 44712 | L11: =IFERROR(IF(J11=C11,K11+D11,K11+VLOOKUP(J11,$C$6:$D$30,2,FALSE))," ") -> 44715 | M11: =IFERROR(IF(N11=0," ",IF(J11=C11,CONCATENATE(E11,", ",F11),CONCATENATE(VLOOKUP(J11,$C$6:$F$30,3,FALSE),", ",VLOOKUP(J11,$C$6:$F$30,4,FALSE))))," ") -> Munich, Germany | N11: =IFERROR(VLOOKUP(J11,$C$6:$F$30,2,FALSE)," ") -> 3
B12: # | C12: 7 | D12: 5 | E12: Berlin | F12: Germany | J12: 7 | K12: =IFERROR(IF(N11=0," ",L11)," ") -> 44715 | L12: =IFERROR(IF(J12=C12,K12+D12,K12+VLOOKUP(J12,$C$6:$D$30,2,FALSE))," ") -> 44720 | M12: =IFERROR(IF(N12=0," ",IF(J12=C12,CONCATENATE(E12,", ",F12),CONCATENATE(VLOOKUP(J12,$C$6:$F$30,3,FALSE),", ",VLOOKUP(J12,$C$6:$F$30,4,FALSE))))," ") -> Berlin, Germany | N12: =IFERROR(VLOOKUP(J12,$C$6:$F$30,2,FALSE)," ") -> 5
B13: # | C13: 8 | D13: 5 | E13: Amsterdam | F13: Netherlands | J13: 8 | K13: =IFERROR(IF(N12=0," ",L12)," ") -> 44720 | L13: =IFERROR(IF(J13=C13,K13+D13,K13+VLOOKUP(J13,$C$6:$D$30,2,FALSE))," ") -> 44725 | M13: =IFERROR(IF(N13=0," ",IF(J13=C13,CONCATENATE(E13,", ",F13),CONCATENATE(VLOOKUP(J13,$C$6:$F$30,3,FALSE),", ",VLOOKUP(J13,$C$6:$F$30,4,FALSE))))," ") -> Amsterdam, Netherlands | N13: =IFERROR(VLOOKUP(J13,$C$6:$F$30,2,FALSE)," ") -> 5
B14: # | C14: 9 | D14: 4 | E14: Copenhagen | F14: Denmark | J14: 9 | K14: =IFERROR(IF(N13=0," ",L13)," ") -> 44725 | L14: =IFERROR(IF(J14=C14,K14+D14,K14+VLOOKUP(J14,$C$6:$D$30,2,FALSE))," ") -> 44729 | M14: =IFERROR(IF(N14=0," ",IF(J14=C14,CONCATENATE(E14,", ",F14),CONCATENATE(VLOOKUP(J14,$C$6:$F$30,3,FALSE),", ",VLOOKUP(J14,$C$6:$F$30,4,FALSE))))," ") -> Copenhagen, Denmark | N14: =IFERROR(VLOOKUP(J14,$C$6:$F$30,2,FALSE)," ") -> 4
B15: # | C15: 10 | D15: 6 | E15: Dublin | F15: Ireland | J15: 10 | K15: =IFERROR(IF(N14=0," ",L14)," ") -> 44729 | L15: =IFERROR(IF(J15=C15,K15+D15,K15+VLOOKUP(J15,$C$6:$D$30,2,FALSE))," ") -> 44735 | M15: =IFERROR(IF(N15=0," ",IF(J15=C15,CONCATENATE(E15,", ",F15),CONCATENATE(VLOOKUP(J15,$C$6:$F$30,3,FALSE),", ",VLOOKUP(J15,$C$6:$F$30,4,FALSE))))," ") -> Dublin, Ireland | N15: =IFERROR(VLOOKUP(J15,$C$6:$F$30,2,FALSE)," ") -> 6
B16: # | C16: 11 | D16: 5 | E16: Edinburgh | F16: Scotland | J16: 11 | K16: =IFERROR(IF(N15=0," ",L15)," ") -> 44735 | L16: =IFERROR(IF(J16=C16,K16+D16,K16+VLOOKUP(J16,$C$6:$D$30,2,FALSE))," ") -> 44740 | M16: =IFERROR(IF(N16=0," ",IF(J16=C16,CONCATENATE(E16,", ",F16),CONCATENATE(VLOOKUP(J16,$C$6:$F$30,3,FALSE),", ",VLOOKUP(J16,$C$6:$F$30,4,FALSE))))," ") -> Edinburgh, Scotland | N16: =IFERROR(VLOOKUP(J16,$C$6:$F$30,2,FALSE)," ") -> 5
B17: # | C17: 12 | D17: 7 | E17: London | F17: England | J17: 12 | K17: =IFERROR(IF(N16=0," ",L16)," ") -> 44740 | L17: =IFERROR(IF(J17=C17,K17+D17,K17+VLOOKUP(J17,$C$6:$D$30,2,FALSE))," ") -> 44747 | M17: =IFERROR(IF(N17=0," ",IF(J17=C17,CONCATENATE(E17,", ",F17),CONCATENATE(VLOOKUP(J17,$C$6:$F$30,3,FALSE),", ",VLOOKUP(J17,$C$6:$F$30,4,FALSE))))," ") -> London, England | N17: =IFERROR(VLOOKUP(J17,$C$6:$F$30,2,FALSE)," ") -> 7
B18: # | C18: 13 | J18: 13 | K18: =IFERROR(IF(N17=0," ",L17)," ") -> 44747 | L18: =IFERROR(IF(J18=C18,K18+D18,K18+VLOOKUP(J18,$C$6:$D$30,2,FALSE))," ") -> 44747 | M18: =IFERROR(IF(N18=0," ",IF(J18=C18,CONCATENATE(E18,", ",F18),CONCATENATE(VLOOKUP(J18,$C$6:$F$30,3,FALSE),", ",VLOOKUP(J18,$C$6:$F$30,4,FALSE))))," ") | N18: =IFERROR(VLOOKUP(J18,$C$6:$F$30,2,FALSE)," ") -> 0
B19: # | C19: 14 | J19: 14 | K19: =IFERROR(IF(N18=0," ",L18)," ") | L19: =IFERROR(IF(J19=C19,K19+D19,K19+VLOOKUP(J19,$C$6:$D$30,2,FALSE))," ") | M19: =IFERROR(IF(N19=0," ",IF(J19=C19,CONCATENATE(E19,", ",F19),CONCATENATE(VLOOKUP(J19,$C$6:$F$30,3,FALSE),", ",VLOOKUP(J19,$C$6:$F$30,4,FALSE))))," ") | N19: =IFERROR(VLOOKUP(J19,$C$6:$F$30,2,FALSE)," ") -> 0
B20: # | C20: 15 | J20: 15 | K20: =IFERROR(IF(N19=0," ",L19)," ") | L20: =IFERROR(IF(J20=C20,K20+D20,K20+VLOOKUP(J20,$C$6:$D$30,2,FALSE))," ") | M20: =IFERROR(IF(N20=0," ",IF(J20=C20,CONCATENATE(E20,", ",F20),CONCATENATE(VLOOKUP(J20,$C$6:$F$30,3,FALSE),", ",VLOOKUP(J20,$C$6:$F$30,4,FALSE))))," ") | N20: =IFERROR(VLOOKUP(J20,$C$6:$F$30,2,FALSE)," ") -> 0
B21: # | C21: 16 | J21: 16 | K21: =IFERROR(IF(N20=0," ",L20)," ") | L21: =IFERROR(IF(J21=C21,K21+D21,K21+VLOOKUP(J21,$C$6:$D$30,2,FALSE))," ") | M21: =IFERROR(IF(N21=0," ",IF(J21=C21,CONCATENATE(E21,", ",F21),CONCATENATE(VLOOKUP(J21,$C$6:$F$30,3,FALSE),", ",VLOOKUP(J21,$C$6:$F$30,4,FALSE))))," ") | N21: =IFERROR(VLOOKUP(J21,$C$6:$F$30,2,FALSE)," ") -> 0
B22: # | C22: 17 | J22: 17 | K22: =IFERROR(IF(N21=0," ",L21)," ") | L22: =IFERROR(IF(J22=C22,K22+D22,K22+VLOOKUP(J22,$C$6:$D$30,2,FALSE))," ") | M22: =IFERROR(IF(N22=0," ",IF(J22=C22,CONCATENATE(E22,", ",F22),CONCATENATE(VLOOKUP(J22,$C$6:$F$30,3,FALSE),", ",VLOOKUP(J22,$C$6:$F$30,4,FALSE))))," ") | N22: =IFERROR(VLOOKUP(J22,$C$6:$F$30,2,FALSE)," ") -> 0
B23: # | C23: 18 | J23: 18 | K23: =IFERROR(IF(N22=0," ",L22)," ") | L23: =IFERROR(IF(J23=C23,K23+D23,K23+VLOOKUP(J23,$C$6:$D$30,2,FALSE))," ") | M23: =IFERROR(IF(N23=0," ",IF(J23=C23,CONCATENATE(E23,", ",F23),CONCATENATE(VLOOKUP(J23,$C$6:$F$30,3,FALSE),", ",VLOOKUP(J23,$C$6:$F$30,4,FALSE))))," ") | N23: =IFERROR(VLOOKUP(J23,$C$6:$F$30,2,FALSE)," ") -> 0
B24: # | C24: 19 | J24: 19 | K24: =IFERROR(IF(N23=0," ",L23)," ") | L24: =IFERROR(IF(J24=C24,K24+D24,K24+VLOOKUP(J24,$C$6:$D$30,2,FALSE))," ") | M24: =IFERROR(IF(N24=0," ",IF(J24=C24,CONCATENATE(E24,", ",F24),CONCATENATE(VLOOKUP(J24,$C$6:$F$30,3,FALSE),", ",VLOOKUP(J24,$C$6:$F$30,4,FALSE))))," ") | N24: =IFERROR(VLOOKUP(J24,$C$6:$F$30,2,FALSE)," ") -> 0
B25: # | C25: 20 | J25: 20 | K25: =IFERROR(IF(N24=0," ",L24)," ") | L25: =IFERROR(IF(J25=C25,K25+D25,K25+VLOOKUP(J25,$C$6:$D$30,2,FALSE))," ") | M25: =IFERROR(IF(N25=0," ",IF(J25=C25,CONCATENATE(E25,", ",F25),CONCATENATE(VLOOKUP(J25,$C$6:$F$30,3,FALSE),", ",VLOOKUP(J25,$C$6:$F$30,4,FALSE))))," ") | N25: =IFERROR(VLOOKUP(J25,$C$6:$F$30,2,FALSE)," ") -> 0
B26: # | C26: 21 | J26: 21 | K26: =IFERROR(IF(N25=0," ",L25)," ") | L26: =IFERROR(IF(J26=C26,K26+D26,K26+VLOOKUP(J26,$C$6:$D$30,2,FALSE))," ") | M26: =IFERROR(IF(N26=0," ",IF(J26=C26,CONCATENATE(E26,", ",F26),CONCATENATE(VLOOKUP(J26,$C$6:$F$30,3,FALSE),", ",VLOOKUP(J26,$C$6:$F$30,4,FALSE))))," ") | N26: =IFERROR(VLOOKUP(J26,$C$6:$F$30,2,FALSE)," ") -> 0
B27: # | C27: 22 | J27: 22 | K27: =IFERROR(IF(N26=0," ",L26)," ") | L27: =IFERROR(IF(J27=C27,K27+D27,K27+VLOOKUP(J27,$C$6:$D$30,2,FALSE))," ") | M27: =IFERROR(IF(N27=0," ",IF(J27=C27,CONCATENATE(E27,", ",F27),CONCATENATE(VLOOKUP(J27,$C$6:$F$30,3,FALSE),", ",VLOOKUP(J27,$C$6:$F$30,4,FALSE))))," ") | N27: =IFERROR(VLOOKUP(J27,$C$6:$F$30,2,FALSE)," ") -> 0
B28: # | C28: 23 | J28: 23 | K28: =IFERROR(IF(N27=0," ",L27)," ") | L28: =IFERROR(IF(J28=C28,K28+D28,K28+VLOOKUP(J28,$C$6:$D$30,2,FALSE))," ") | M28: =IFERROR(IF(N28=0," ",IF(J28=C28,CONCATENATE(E28,", ",F28),CONCATENATE(VLOOKUP(J28,$C$6:$F$30,3,FALSE),", ",VLOOKUP(J28,$C$6:$F$30,4,FALSE))))," ") | N28: =IFERROR(VLOOKUP(J28,$C$6:$F$30,2,FALSE)," ") -> 0
B29: # | C29: 24 | J29: 24 | K29: =IFERROR(IF(N28=0," ",L28)," ") | L29: =IFERROR(IF(J29=C29,K29+D29,K29+VLOOKUP(J29,$C$6:$D$30,2,FALSE))," ") | M29: =IFERROR(IF(N29=0," ",IF(J29=C29,CONCATENATE(E29,", ",F29),CONCATENATE(VLOOKUP(J29,$C$6:$F$30,3,FALSE),", ",VLOOKUP(J29,$C$6:$F$30,4,FALSE))))," ") | N29: =IFERROR(VLOOKUP(J29,$C$6:$F$30,2,FALSE)," ") -> 0
B30: # | C30: 25 | J30: 25 | K30: =IFERROR(IF(N29=0," ",L29)," ") | L30: =IFERROR(IF(J30=C30,K30+D30,K30+VLOOKUP(J30,$C$6:$D$30,2,FALSE))," ") | M30: =IFERROR(IF(N30=0," ",IF(J30=C30,CONCATENATE(E30,", ",F30),CONCATENATE(VLOOKUP(J30,$C$6:$F$30,3,FALSE),", ",VLOOKUP(J30,$C$6:$F$30,4,FALSE))))," ") | N30: =IFERROR(VLOOKUP(J30,$C$6:$F$30,2,FALSE)," ") -> 0

Sheet Itinerary Calendar
B1: Trip Itinerary Calendar | F1: Auto Calendar Settings
B2: This is where you can find the calendar plan of your trip. | F2: Start Date | G2: Year Start | H2: Month # Start | M2: Start Month 2 | N2: =IF((DreamStartMonth+1)<=12,DreamStartMonth+1,1) -> 6
F3: =DreamStartDate -> 44694 | G3: =YEAR(DreamStartDate) -> 2022 | H3: =MONTH(DreamStartDate) -> 5 | M3: Start Month 3 | N3: =IF((DreamStartMonth+2)<=12,DreamStartMonth+2,IF((DreamStartMonth+2)<=13,1,2)) -> 7
B5: Friday
B6: 1 Location Accomodation for that night
B7: TRAVEL DAY
B8: Travel Plan
B9: *Choose the contents you want
B10: {=(_xlfn.IFS(H3=1,"January ",H3=2,"February ",H3=3,"March ",H3=4,"April ",H3=5,"May ",H3=6,"June ",H3=7,"July ",H3=8,"August ",H3=9,"September ",H3=10,"October ",H3=11,"November ",H3=12,"December "))&YEAR(B17)} -> May 2022
B11: Sunday | C11: Monday | D11: Tuesday | E11: Wednesday | F11: Thursday | G11: Friday | H11: Saturday
B12: ='Itinerary-CODE'!B4 -> 44682 | C12: ='Itinerary-CODE'!C4 -> 44683 | D12: ='Itinerary-CODE'!D4 -> 44684 | E12: ='Itinerary-CODE'!E4 -> 44685 | F12: ='Itinerary-CODE'!F4 -> 44686 | G12: ='Itinerary-CODE'!G4 -> 44687 | H12: ='Itinerary-CODE'!H4 -> 44688
B13: =IFERROR(VLOOKUP(B12,Itinerary!$B$9:$E$108,2,FALSE)," ") | C13: =IFERROR(VLOOKUP(C12,Itinerary!$B$9:$E$108,2,FALSE)," ") | D13: =IFERROR(VLOOKUP(D12,Itinerary!$B$9:$E$108,2,FALSE)," ") | E13: =IFERROR(VLOOKUP(E12,Itinerary!$B$9:$E$108,2,FALSE)," ") | F13: =IFERROR(VLOOKUP(F12,Itinerary!$B$9:$E$108,2,FALSE)," ") | G13: =IFERROR(VLOOKUP(G12,Itinerary!$B$9:$E$108,2,FALSE)," ") | H13: =IFERROR(VLOOKUP(H12,Itinerary!$B$9:$E$108,2,FALSE)," ")
B14: =IFERROR(VLOOKUP(B12,Itinerary!$B$9:$E$108,3,FALSE)," ") | C14: =IFERROR(VLOOKUP(C12,Itinerary!$B$9:$E$108,3,FALSE)," ") | D14: =IFERROR(VLOOKUP(D12,Itinerary!$B$9:$E$108,3,FALSE)," ") | E14: =IFERROR(VLOOKUP(E12,Itinerary!$B$9:$E$108,3,FALSE)," ") | F14: =IFERROR(VLOOKUP(F12,Itinerary!$B$9:$E$108,3,FALSE)," ") | G14: =IFERROR(VLOOKUP(G12,Itinerary!$B$9:$E$108,3,FALSE)," ") | H14: =IFERROR(VLOOKUP(H12,Itinerary!$B$9:$E$108,3,FALSE)," ")
B15: =IFERROR(IF(VLOOKUP(B12,Itinerary!$B$9:$E$108,4,FALSE)="Yes","TRAVEL DAY"," ")," ") | C15: =IFERROR(IF(VLOOKUP(C12,Itinerary!$B$9:$E$108,4,FALSE)="Yes","TRAVEL DAY"," ")," ") | D15: =IFERROR(IF(VLOOKUP(D12,Itinerary!$B$9:$E$108,4,FALSE)="Yes","TRAVEL DAY"," ")," ") | E15: =IFERROR(IF(VLOOKUP(E12,Itinerary!$B$9:$E$108,4,FALSE)="Yes","TRAVEL DAY"," ")," ") | F15: =IFERROR(IF(VLOOKUP(F12,Itinerary!$B$9:$E$108,4,FALSE)="Yes","TRAVEL DAY"," ")," ") | G15: =IFERROR(IF(VLOOKUP(G12,Itinerary!$B$9:$E$108,4,FALSE)="Yes","TRAVEL DAY"," ")," ") | H15: =IFERROR(IF(VLOOKUP(H12,Itinerary!$B$9:$E$108,4,FALSE)="Yes","TRAVEL DAY"," ")," ")
B17: ='Itinerary-CODE'!B5 -> 44689 | C17: ='Itinerary-CODE'!C5 -> 44690 | D17: ='Itinerary-CODE'!D5 -> 44691 | E17: ='Itinerary-CODE'!E5 -> 44692 | F17: ='Itinerary-CODE'!F5 -> 44693 | G17: ='Itinerary-CODE'!G5 -> 44694 | H17: ='Itinerary-CODE'!H5 -> 44695
B18: =IFERROR(VLOOKUP(B17,Itinerary!$B$9:$E$108,2,FALSE)," ") | C18: =IFERROR(VLOOKUP(C17,Itinerary!$B$9:$E$108,2,FALSE)," ") | D18: =IFERROR(VLOOKUP(D17,Itinerary!$B$9:$E$108,2,FALSE)," ") | E18: =IFERROR(VLOOKUP(E17,Itinerary!$B$9:$E$108,2,FALSE)," ") | F18: =IFERROR(VLOOKUP(F17,Itinerary!$B$9:$E$108,2,FALSE)," ") | G18: =IFERROR(VLOOKUP(G17,Itinerary!$B$9:$E$108,2,FALSE)," ") -> Zurich, Switzerland | H18: =IFERROR(VLOOKUP(H17,Itinerary!$B$9:$E$108,2,FALSE)," ") -> Zurich, Switzerland
B19: =IFERROR(VLOOKUP(B17,Itinerary!$B$9:$E$108,3,FALSE)," ") | C19: =IFERROR(VLOOKUP(C17,Itinerary!$B$9:$E$108,3,FALSE)," ") | D19: =IFERROR(VLOOKUP(D17,Itinerary!$B$9:$E$108,3,FALSE)," ") | E19: =IFERROR(VLOOKUP(E17,Itinerary!$B$9:$E$108,3,FALSE)," ") | F19: =IFERROR(VLOOKUP(F17,Itinerary!$B$9:$E$108,3,FALSE)," ") | G19: =IFERROR(VLOOKUP(G17,Itinerary!$B$9:$E$108,3,FALSE)," ") -> Zurich Youth Hostel | H19: =IFERROR(VLOOKUP(H17,Itinerary!$B$9:$E$108,3,FALSE)," ") -> Zurich Youth Hostel
B20: =IFERROR(IF(VLOOKUP(B17,Itinerary!$B$9:$E$108,4,FALSE)="Yes","TRAVEL DAY"," ")," ") | C20: =IFERROR(IF(VLOOKUP(C17,Itinerary!$B$9:$E$108,4,FALSE)="Yes","TRAVEL DAY"," ")," ") | D20: =IFERROR(IF(VLOOKUP(D17,Itinerary!$B$9:$E$108,4,FALSE)="Yes","TRAVEL DAY"," ")," ") | E20: =IFERROR(IF(VLOOKUP(E17,Itinerary!$B$9:$E$108,4,FALSE)="Yes","TRAVEL DAY"," ")," ") | F20: =IFERROR(IF(VLOOKUP(F17,Itinerary!$B$9:$E$108,4,FALSE)="Yes","TRAVEL DAY"," ")," ") | G20: =IFERROR(IF(VLOOKUP(G17,Itinerary!$B$9:$E$108,4,FALSE)="Yes","TRAVEL DAY"," ")," ") -> TRAVEL DAY | H20: =IFERROR(IF(VLOOKUP(H17,Itinerary!$B$9:$E$108,4,FALSE)="Yes","TRAVEL DAY"," ")," ")
B22: ='Itinerary-CODE'!B6 -> 44696 | C22: ='Itinerary-CODE'!C6 -> 44697 | D22: ='Itinerary-CODE'!D6 -> 44698 | E22: ='Itinerary-CODE'!E6 -> 44699 | F22: ='Itinerary-CODE'!F6 -> 44700 | G22: ='Itinerary-CODE'!G6 -> 44701 | H22: ='Itinerary-CODE'!H6 -> 44702
B23: =IFERROR(VLOOKUP(B22,Itinerary!$B$9:$E$108,2,FALSE)," ") -> Zurich, Switzerland | C23: =IFERROR(VLOOKUP(C22,Itinerary!$B$9:$E$108,2,FALSE)," ") -> Lucerne, Switzerland | D23: =IFERROR(VLOOKUP(D22,Itinerary!$B$9:$E$108,2,FALSE)," ") -> Lucerne, Switzerland | E23: =IFERROR(VLOOKUP(E22,Itinerary!$B$9:$E$108,2,FALSE)," ") -> Lucerne, Switzerland | F23: =IFERROR(VLOOKUP(F22,Itinerary!$B$9:$E$108,2,FALSE)," ") -> Salzburg, Austria | G23: =IFERROR(VLOOKUP(G22,Itinerary!$B$9:$E$108,2,FALSE)," ") -> Salzburg, Austria | H23: =IFERROR(VLOOKUP(H22,Itinerary!$B$9:$E$108,2,FALSE)," ") -> Salzburg, Austria
B24: =IFERROR(VLOOKUP(B22,Itinerary!$B$9:$E$108,3,FALSE)," ") -> Zurich Youth Hostel | C24: =IFERROR(VLOOKUP(C22,Itinerary!$B$9:$E$108,3,FALSE)," ") -> Barabas Luzern | D24: =IFERROR(VLOOKUP(D22,Itinerary!$B$9:$E$108,3,FALSE)," ") -> Barabas Luzern | E24: =IFERROR(VLOOKUP(E22,Itinerary!$B$9:$E$108,3,FALSE)," ") -> Barabas Luzern | F24: =IFERROR(VLOOKUP(F22,Itinerary!$B$9:$E$108,3,FALSE)," ") -> Chalet Hostel @ Backpackers Villa | G24: =IFERROR(VLOOKUP(G22,Itinerary!$B$9:$E$108,3,FALSE)," ") -> Chalet Hostel @ Backpackers Villa | H24: =IFERROR(VLOOKUP(H22,Itinerary!$B$9:$E$108,3,FALSE)," ") -> Chalet Hostel @ Backpackers Villa
B25: =IFERROR(IF(VLOOKUP(B22,Itinerary!$B$9:$E$108,4,FALSE)="Yes","TRAVEL DAY"," ")," ") | C25: =IFERROR(IF(VLOOKUP(C22,Itinerary!$B$9:$E$108,4,FALSE)="Yes","TRAVEL DAY"," ")," ") -> TRAVEL DAY | D25: =IFERROR(IF(VLOOKUP(D22,Itinerary!$B$9:$E$108,4,FALSE)="Yes","TRAVEL DAY"," ")," ") | E25: =IFERROR(IF(VLOOKUP(E22,Itinerary!$B$9:$E$108,4,FALSE)="Yes","TRAVEL DAY"," ")," ") | F25: =IFERROR(IF(VLOOKUP(F22,Itinerary!$B$9:$E$108,4,FALSE)="Yes","TRAVEL DAY"," ")," ") -> TRAVEL DAY | G25: =IFERROR(IF(VLOOKUP(G22,Itinerary!$B$9:$E$108,4,FALSE)="Yes","TRAVEL DAY"," ")," ") | H25: =IFERROR(IF(VLOOKUP(H22,Itinerary!$B$9:$E$108,4,FALSE)="Yes","TRAVEL DAY"," ")," ")
B27: ='Itinerary-CODE'!B7 -> 44703 | C27: ='Itinerary-CODE'!C7 -> 44704 | D27: ='Itinerary-CODE'!D7 -> 44705 | E27: ='Itinerary-CODE'!E7 -> 44706 | F27: ='Itinerary-CODE'!F7 -> 44707 | G27: ='Itinerary-CODE'!G7 -> 44708 | H27: ='Itinerary-CODE'!H7 -> 44709
B28: =IFERROR(VLOOKUP(B27,Itinerary!$B$9:$E$108,2,FALSE)," ") -> Salzburg, Austria | C28: =IFERROR(VLOOKUP(C27,Itinerary!$B$9:$E$108,2,FALSE)," ") -> Interlaken, Switzerland | D28: =IFERROR(VLOOKUP(D27,Itinerary!$B$9:$E$108,2,FALSE)," ") -> Interlaken, Switzerland | E28: =IFERROR(VLOOKUP(E27,Itinerary!$B$9:$E$108,2,FALSE)," ") -> Interlaken, Switzerland | F28: =IFERROR(VLOOKUP(F27,Itinerary!$B$9:$E$108,2,FALSE)," ") -> Interlaken, Switzerland | G28: =IFERROR(VLOOKUP(G27,Itinerary!$B$9:$E$108,2,FALSE)," ") -> Interlaken, Switzerland | H28: =IFERROR(VLOOKUP(H27,Itinerary!$B$9:$E$108,2,FALSE)," ") -> Interlaken, Switzerland
B29: =IFERROR(VLOOKUP(B27,Itinerary!$B$9:$E$108,3,FALSE)," ") -> Chalet Hostel @ Backpackers Villa | C29: =IFERROR(VLOOKUP(C27,Itinerary!$B$9:$E$108,3,FALSE)," ") -> YoHo - Internationall Youth Hostel | D29: =IFERROR(VLOOKUP(D27,Itinerary!$B$9:$E$108,3,FALSE)," ") -> YoHo - Internationall Youth Hostel | E29: =IFERROR(VLOOKUP(E27,Itinerary!$B$9:$E$108,3,FALSE)," ") -> YoHo - Internationall Youth Hostel | F29: =IFERROR(VLOOKUP(F27,Itinerary!$B$9:$E$108,3,FALSE)," ") -> YoHo - Internationall Youth Hostel | G29: =IFERROR(VLOOKUP(G27,Itinerary!$B$9:$E$108,3,FALSE)," ") -> YoHo - Internationall Youth Hostel | H29: =IFERROR(VLOOKUP(H27,Itinerary!$B$9:$E$108,3,FALSE)," ") -> YoHo - Internationall Youth Hostel
B30: =IFERROR(IF(VLOOKUP(B27,Itinerary!$B$9:$E$108,4,FALSE)="Yes","TRAVEL DAY"," ")," ") | C30: =IFERROR(IF(VLOOKUP(C27,Itinerary!$B$9:$E$108,4,FALSE)="Yes","TRAVEL DAY"," ")," ") -> TRAVEL DAY | D30: =IFERROR(IF(VLOOKUP(D27,Itinerary!$B$9:$E$108,4,FALSE)="Yes","TRAVEL DAY"," ")," ") | E30: =IFERROR(IF(VLOOKUP(E27,Itinerary!$B$9:$E$108,4,FALSE)="Yes","TRAVEL DAY"," ")," ") | F30: =IFERROR(IF(VLOOKUP(F27,Itinerary!$B$9:$E$108,4,FALSE)="Yes","TRAVEL DAY"," ")," ") | G30: =IFERROR(IF(VLOOKUP(G27,Itinerary!$B$9:$E$108,4,FALSE)="Yes","TRAVEL DAY"," ")," ") | H30: =IFERROR(IF(VLOOKUP(H27,Itinerary!$B$9:$E$108,4,FALSE)="Yes","TRAVEL DAY"," ")," ")
B32: ='Itinerary-CODE'!B8 -> 44710 | C32: ='Itinerary-CODE'!C8 -> 44711 | D32: ='Itinerary-CODE'!D8 -> 44712 | E32: ='Itinerary-CODE'!E8 | F32: ='Itinerary-CODE'!F8 | G32: ='Itinerary-CODE'!G8 | H32: ='Itinerary-CODE'!H8
B33: =IFERROR(VLOOKUP(B32,Itinerary!$B$9:$E$108,2,FALSE)," ") -> Interlaken, Switzerland | C33: =IFERROR(VLOOKUP(C32,Itinerary!$B$9:$E$108,2,FALSE)," ") -> Halstatt, Austria | D33: =IFERROR(VLOOKUP(D32,Itinerary!$B$9:$E$108,2,FALSE)," ") -> Munich, Germany | E33: =IFERROR(VLOOKUP(E32,Itinerary!$B$9:$E$108,2,FALSE)," ") | F33: =IFERROR(VLOOKUP(F32,Itinerary!$B$9:$E$108,2,FALSE)," ") | G33: =IFERROR(VLOOKUP(G32,Itinerary!$B$9:$E$108,2,FALSE)," ") | H33: =IFERROR(VLOOKUP(H32,Itinerary!$B$9:$E$108,2,FALSE)," ")
B34: =IFERROR(VLOOKUP(B32,Itinerary!$B$9:$E$108,3,FALSE)," ") -> YoHo - Internationall Youth Hostel | C34: =IFERROR(VLOOKUP(C32,Itinerary!$B$9:$E$108,3,FALSE)," ") -> Pension Leopoldine | D34: =IFERROR(VLOOKUP(D32,Itinerary!$B$9:$E$108,3,FALSE)," ") -> Wombat's City Hostel Munich | E34: =IFERROR(VLOOKUP(E32,Itinerary!$B$9:$E$108,3,FALSE)," ") | F34: =IFERROR(VLOOKUP(F32,Itinerary!$B$9:$E$108,3,FALSE)," ") | G34: =IFERROR(VLOOKUP(G32,Itinerary!$B$9:$E$108,3,FALSE)," ") | H34: =IFERROR(VLOOKUP(H32,Itinerary!$B$9:$E$108,3,FALSE)," ")
B35: =IFERROR(IF(VLOOKUP(B32,Itinerary!$B$9:$E$108,4,FALSE)="Yes","TRAVEL DAY"," ")," ") | C35: =IFERROR(IF(VLOOKUP(C32,Itinerary!$B$9:$E$108,4,FALSE)="Yes","TRAVEL DAY"," ")," ") -> TRAVEL DAY | D35: =IFERROR(IF(VLOOKUP(D32,Itinerary!$B$9:$E$108,4,FALSE)="Yes","TRAVEL DAY"," ")," ") -> TRAVEL DAY | E35: =IFERROR(IF(VLOOKUP(E32,Itinerary!$B$9:$E$108,4,FALSE)="Yes","TRAVEL DAY"," ")," ") | F35: =IFERROR(IF(VLOOKUP(F32,Itinerary!$B$9:$E$108,4,FALSE)="Yes","TRAVEL DAY"," ")," ") | G35: =IFERROR(IF(VLOOKUP(G32,Itinerary!$B$9:$E$108,4,FALSE)="Yes","TRAVEL DAY"," ")," ") | H35: =IFERROR(IF(VLOOKUP(H32,Itinerary!$B$9:$E$108,4,FALSE)="Yes","TRAVEL DAY"," ")," ")
B37: ='Itinerary-CODE'!B9 | C37: ='Itinerary-CODE'!C9 | E37: Notes:
B38: =IFERROR(VLOOKUP(B37,Itinerary!$B$9:$E$108,2,FALSE)," ") | C38: =IFERROR(VLOOKUP(C37,Itinerary!$B$9:$E$108,2,FALSE)," ") | D38: =IFERROR(VLOOKUP(D37,Itinerary!$B$9:$E$108,2,FALSE)," ")
B40: =IFERROR(IF(VLOOKUP(B37,Itinerary!$B$9:$E$108,4,FALSE)="Yes","TRAVEL DAY"," ")," ") | C40: =IFERROR(IF(VLOOKUP(C37,Itinerary!$B$9:$E$108,4,FALSE)="Yes","TRAVEL DAY"," ")," ") | D40: =IFERROR(IF(VLOOKUP(D37,Itinerary!$B$9:$E$108,4,FALSE)="Yes","TRAVEL DAY"," ")," ")
B42: {=(_xlfn.IFS(DreamStartMonth2=1,"January ",DreamStartMonth2=2,"February ",DreamStartMonth2=3,"March ",DreamStartMonth2=4,"April ",DreamStartMonth2=5,"May ",DreamStartMonth2=6,"June ",DreamStartMonth2=7,"July ",DreamStartMonth2=8,"August ",DreamStartMonth2=9,"September ",DreamStartMonth2=10,"October ",DreamStartMonth2=11,"November ",DreamStartMonth2=12,"December "))&YEAR(B49)} -> June 2022
B43: Sunday | C43: Monday | D43: Tuesday | E43: Wednesday | F43: Thursday | G43: Friday | H43: Saturday
B44: ='Itinerary-CODE'!B10 | C44: ='Itinerary-CODE'!C10 | D44: ='Itinerary-CODE'!D10 | E44: ='Itinerary-CODE'!E10 -> 44713 | F44: ='Itinerary-CODE'!F10 -> 44714 | G44: ='Itinerary-CODE'!G10 -> 44715 | H44: ='Itinerary-CODE'!H10 -> 44716
B45: =IFERROR(VLOOKUP(B44,Itinerary!$B$9:$E$108,2,FALSE)," ") | C45: =IFERROR(VLOOKUP(C44,Itinerary!$B$9:$E$108,2,FALSE)," ") | D45: =IFERROR(VLOOKUP(D44,Itinerary!$B$9:$E$108,2,FALSE)," ") | E45: =IFERROR(VLOOKUP(E44,Itinerary!$B$9:$E$108,2,FALSE)," ") -> Munich, Germany | F45: =IFERROR(VLOOKUP(F44,Itinerary!$B$9:$E$108,2,FALSE)," ") -> Munich, Germany | G45: =IFERROR(VLOOKUP(G44,Itinerary!$B$9:$E$108,2,FALSE)," ") -> Berlin, Germany | H45: =IFERROR(VLOOKUP(H44,Itinerary!$B$9:$E$108,2,FALSE)," ") -> Berlin, Germany
B46: =IFERROR(VLOOKUP(B44,Itinerary!$B$9:$E$108,3,FALSE)," ") | C46: =IFERROR(VLOOKUP(C44,Itinerary!$B$9:$E$108,3,FALSE)," ") | D46: =IFERROR(VLOOKUP(D44,Itinerary!$B$9:$E$108,3,FALSE)," ") | E46: =IFERROR(VLOOKUP(E44,Itinerary!$B$9:$E$108,3,FALSE)," ") -> Wombat's City Hostel Munich | F46: =IFERROR(VLOOKUP(F44,Itinerary!$B$9:$E$108,3,FALSE)," ") -> Wombat's City Hostel Munich | G46: =IFERROR(VLOOKUP(G44,Itinerary!$B$9:$E$108,3,FALSE)," ") -> St. Christophers Inn Berlin | H46: =IFERROR(VLOOKUP(H44,Itinerary!$B$9:$E$108,3,FALSE)," ") -> St. Christophers Inn Berlin
B47: =IFERROR(IF(VLOOKUP(B44,Itinerary!$B$9:$E$108,4,FALSE)="Yes","TRAVEL DAY"," ")," ") | C47: =IFERROR(IF(VLOOKUP(C44,Itinerary!$B$9:$E$108,4,FALSE)="Yes","TRAVEL DAY"," ")," ") | D47: =IFERROR(IF(VLOOKUP(D44,Itinerary!$B$9:$E$108,4,FALSE)="Yes","TRAVEL DAY"," ")," ") | E47: =IFERROR(IF(VLOOKUP(E44,Itinerary!$B$9:$E$108,4,FALSE)="Yes","TRAVEL DAY"," ")," ") | F47: =IFERROR(IF(VLOOKUP(F44,Itinerary!$B$9:$E$108,4,FALSE)="Yes","TRAVEL DAY"," ")," ") | G47: =IFERROR(IF(VLOOKUP(G44,Itinerary!$B$9:$E$108,4,FALSE)="Yes","TRAVEL DAY"," ")," ") -> TRAVEL DAY | H47: =IFERROR(IF(VLOOKUP(H44,Itinerary!$B$9:$E$108,4,FALSE)="Yes","TRAVEL DAY"," ")," ")
B49: ='Itinerary-CODE'!B11 -> 44717 | C49: ='Itinerary-CODE'!C11 -> 44718 | D49: ='Itinerary-CODE'!D11 -> 44719 | E49: ='Itinerary-CODE'!E11 -> 44720 | F49: ='Itinerary-CODE'!F11 -> 44721 | G49: ='Itinerary-CODE'!G11 -> 44722 | H49: ='Itinerary-CODE'!H11 -> 44723
...

Sheet Itinerary
B2: Itinerary - Detailed
B3: This spreadsheet is a comprehensive list of your trip!
B8: Date | C8: Location | D8: Accomodation | E8: Traveling? | F8: Travel Plan | G8: Day Plan/Activities | H8: Today's Budget | I8: Notes
B9: =DreamStartDate -> 44694 | C9: =VLOOKUP(B9,'Trip Dreaming'!$K$6:$M$30,3,TRUE) -> Zurich, Switzerland | D9: =IF(VLOOKUP(B9,Accomodations!$B$7:$F$31,5,TRUE)=0," ",VLOOKUP(B9,Accomodations!$B$7:$F$31,5,TRUE)) -> Zurich Youth Hostel | E9: Yes | F9: Fly in from DFW
B10: =B9+1 -> 44695 | C10: =VLOOKUP(B10,'Trip Dreaming'!$K$6:$M$30,3,TRUE) -> Zurich, Switzerland | D10: =IF(VLOOKUP(B10,Accomodations!$B$7:$F$31,5,TRUE)=0," ",VLOOKUP(B10,Accomodations!$B$7:$F$31,5,TRUE)) -> Zurich Youth Hostel | E10: =IF(Table2[[#This Row],[Location]]=C9," ", "Yes") | G10: Walk around old town
B11: =B10+1 -> 44696 | C11: =VLOOKUP(B11,'Trip Dreaming'!$K$6:$M$30,3,TRUE) -> Zurich, Switzerland | D11: =IF(VLOOKUP(B11,Accomodations!$B$7:$F$31,5,TRUE)=0," ",VLOOKUP(B11,Accomodations!$B$7:$F$31,5,TRUE)) -> Zurich Youth Hostel | E11: =IF(Table2[[#This Row],[Location]]=C10," ", "Yes") | G11: Walk around old town
B12: =B11+1 -> 44697 | C12: =VLOOKUP(B12,'Trip Dreaming'!$K$6:$M$30,3,TRUE) -> Lucerne, Switzerland | D12: =IF(VLOOKUP(B12,Accomodations!$B$7:$F$31,5,TRUE)=0," ",VLOOKUP(B12,Accomodations!$B$7:$F$31,5,TRUE)) -> Barabas Luzern | E12: =IF(Table2[[#This Row],[Location]]=C11," ", "Yes") -> Yes | F12: Eurorail Train
B13: =B12+1 -> 44698 | C13: =VLOOKUP(B13,'Trip Dreaming'!$K$6:$M$30,3,TRUE) -> Lucerne, Switzerland | D13: =IF(VLOOKUP(B13,Accomodations!$B$7:$F$31,5,TRUE)=0," ",VLOOKUP(B13,Accomodations!$B$7:$F$31,5,TRUE)) -> Barabas Luzern | E13: =IF(Table2[[#This Row],[Location]]=C12," ", "Yes") | G13: Hike Mt. Pilatus
B14: =B13+1 -> 44699 | C14: =VLOOKUP(B14,'Trip Dreaming'!$K$6:$M$30,3,TRUE) -> Lucerne, Switzerland | D14: =IF(VLOOKUP(B14,Accomodations!$B$7:$F$31,5,TRUE)=0," ",VLOOKUP(B14,Accomodations!$B$7:$F$31,5,TRUE)) -> Barabas Luzern | E14: =IF(Table2[[#This Row],[Location]]=C13," ", "Yes")
B15: =B14+1 -> 44700 | C15: =VLOOKUP(B15,'Trip Dreaming'!$K$6:$M$30,3,TRUE) -> Salzburg, Austria | D15: =IF(VLOOKUP(B15,Accomodations!$B$7:$F$31,5,TRUE)=0," ",VLOOKUP(B15,Accomodations!$B$7:$F$31,5,TRUE)) -> Chalet Hostel @ Backpackers Villa | E15: =IF(Table2[[#This Row],[Location]]=C14," ", "Yes") -> Yes | F15: Eurorail Train | G15: Hike in Lauterbrunnen
B16: =B15+1 -> 44701 | C16: =VLOOKUP(B16,'Trip Dreaming'!$K$6:$M$30,3,TRUE) -> Salzburg, Austria | D16: =IF(VLOOKUP(B16,Accomodations!$B$7:$F$31,5,TRUE)=0," ",VLOOKUP(B16,Accomodations!$B$7:$F$31,5,TRUE)) -> Chalet Hostel @ Backpackers Villa | E16: =IF(Table2[[#This Row],[Location]]=C15," ", "Yes") | G16: Hike in Grindelwald
B17: =B16+1 -> 44702 | C17: =VLOOKUP(B17,'Trip Dreaming'!$K$6:$M$30,3,TRUE) -> Salzburg, Austria | D17: =IF(VLOOKUP(B17,Accomodations!$B$7:$F$31,5,TRUE)=0," ",VLOOKUP(B17,Accomodations!$B$7:$F$31,5,TRUE)) -> Chalet Hostel @ Backpackers Villa | E17: =IF(Table2[[#This Row],[Location]]=C16," ", "Yes") | G17: Hike Mt. Eiger
B18: =B17+1 -> 44703 | C18: =VLOOKUP(B18,'Trip Dreaming'!$K$6:$M$30,3,TRUE) -> Salzburg, Austria | D18: =IF(VLOOKUP(B18,Accomodations!$B$7:$F$31,5,TRUE)=0," ",VLOOKUP(B18,Accomodations!$B$7:$F$31,5,TRUE)) -> Chalet Hostel @ Backpackers Villa | E18: =IF(Table2[[#This Row],[Location]]=C17," ", "Yes") | G18: Go to Basel
B19: =B18+1 -> 44704 | C19: =VLOOKUP(B19,'Trip Dreaming'!$K$6:$M$30,3,TRUE) -> Interlaken, Switzerland | D19: =IF(VLOOKUP(B19,Accomodations!$B$7:$F$31,5,TRUE)=0," ",VLOOKUP(B19,Accomodations!$B$7:$F$31,5,TRUE)) -> YoHo - Internationall Youth Hostel | E19: =IF(Table2[[#This Row],[Location]]=C18," ", "Yes") -> Yes | G19: Hike to Murren
B20: =B19+1 -> 44705 | C20: =VLOOKUP(B20,'Trip Dreaming'!$K$6:$M$30,3,TRUE) -> Interlaken, Switzerland | D20: =IF(VLOOKUP(B20,Accomodations!$B$7:$F$31,5,TRUE)=0," ",VLOOKUP(B20,Accomodations!$B$7:$F$31,5,TRUE)) -> YoHo - Internationall Youth Hostel | E20: =IF(Table2[[#This Row],[Location]]=C19," ", "Yes") | G20: Visit Basel
B21: =B20+1 -> 44706 | C21: =VLOOKUP(B21,'Trip Dreaming'!$K$6:$M$30,3,TRUE) -> Interlaken, Switzerland | D21: =IF(VLOOKUP(B21,Accomodations!$B$7:$F$31,5,TRUE)=0," ",VLOOKUP(B21,Accomodations!$B$7:$F$31,5,TRUE)) -> YoHo - Internationall Youth Hostel | E21: =IF(Table2[[#This Row],[Location]]=C20," ", "Yes") | G21: Hike in Interlaken
B22: =B21+1 -> 44707 | C22: =VLOOKUP(B22,'Trip Dreaming'!$K$6:$M$30,3,TRUE) -> Interlaken, Switzerland | D22: =IF(VLOOKUP(B22,Accomodations!$B$7:$F$31,5,TRUE)=0," ",VLOOKUP(B22,Accomodations!$B$7:$F$31,5,TRUE)) -> YoHo - Internationall Youth Hostel | E22: =IF(Table2[[#This Row],[Location]]=C21," ", "Yes") | F22: Eurorail Train
B23: =B22+1 -> 44708 | C23: =VLOOKUP(B23,'Trip Dreaming'!$K$6:$M$30,3,TRUE) -> Interlaken, Switzerland | D23: =IF(VLOOKUP(B23,Accomodations!$B$7:$F$31,5,TRUE)=0," ",VLOOKUP(B23,Accomodations!$B$7:$F$31,5,TRUE)) -> YoHo - Internationall Youth Hostel | E23: =IF(Table2[[#This Row],[Location]]=C22," ", "Yes") | G23: Go to Augustiner Brewery
B24: =B23+1 -> 44709 | C24: =VLOOKUP(B24,'Trip Dreaming'!$K$6:$M$30,3,TRUE) -> Interlaken, Switzerland | D24: =IF(VLOOKUP(B24,Accomodations!$B$7:$F$31,5,TRUE)=0," ",VLOOKUP(B24,Accomodations!$B$7:$F$31,5,TRUE)) -> YoHo - Internationall Youth Hostel | E24: =IF(Table2[[#This Row],[Location]]=C23," ", "Yes") | G24: Sound of Music Tour
B25: =B24+1 -> 44710 | C25: =VLOOKUP(B25,'Trip Dreaming'!$K$6:$M$30,3,TRUE) -> Interlaken, Switzerland | D25: =IF(VLOOKUP(B25,Accomodations!$B$7:$F$31,5,TRUE)=0," ",VLOOKUP(B25,Accomodations!$B$7:$F$31,5,TRUE)) -> YoHo - Internationall Youth Hostel | E25: =IF(Table2[[#This Row],[Location]]=C24," ", "Yes") | G25: Walk to Castle
B26: =B25+1 -> 44711 | C26: =VLOOKUP(B26,'Trip Dreaming'!$K$6:$M$30,3,TRUE) -> Halstatt, Austria | D26: =IF(VLOOKUP(B26,Accomodations!$B$7:$F$31,5,TRUE)=0," ",VLOOKUP(B26,Accomodations!$B$7:$F$31,5,TRUE)) -> Pension Leopoldine | E26: =IF(Table2[[#This Row],[Location]]=C25," ", "Yes") -> Yes | F26: Eurorail Train | G26: Chill
B27: =B26+1 -> 44712 | C27: =VLOOKUP(B27,'Trip Dreaming'!$K$6:$M$30,3,TRUE) -> Munich, Germany | D27: =IF(VLOOKUP(B27,Accomodations!$B$7:$F$31,5,TRUE)=0," ",VLOOKUP(B27,Accomodations!$B$7:$F$31,5,TRUE)) -> Wombat's City Hostel Munich | E27: =IF(Table2[[#This Row],[Location]]=C26," ", "Yes") -> Yes | F27: Eurorail Train | G27: Go to clubs
B28: =B27+1 -> 44713 | C28: =VLOOKUP(B28,'Trip Dreaming'!$K$6:$M$30,3,TRUE) -> Munich, Germany | D28: =IF(VLOOKUP(B28,Accomodations!$B$7:$F$31,5,TRUE)=0," ",VLOOKUP(B28,Accomodations!$B$7:$F$31,5,TRUE)) -> Wombat's City Hostel Munich | E28: =IF(Table2[[#This Row],[Location]]=C27," ", "Yes") | G28: Go to clubs
B29: =B28+1 -> 44714 | C29: =VLOOKUP(B29,'Trip Dreaming'!$K$6:$M$30,3,TRUE) -> Munich, Germany | D29: =IF(VLOOKUP(B29,Accomodations!$B$7:$F$31,5,TRUE)=0," ",VLOOKUP(B29,Accomodations!$B$7:$F$31,5,TRUE)) -> Wombat's City Hostel Munich | E29: =IF(Table2[[#This Row],[Location]]=C28," ", "Yes") | G29: Go to clubs
B30: =B29+1 -> 44715 | C30: =VLOOKUP(B30,'Trip Dreaming'!$K$6:$M$30,3,TRUE) -> Berlin, Germany | D30: =IF(VLOOKUP(B30,Accomodations!$B$7:$F$31,5,TRUE)=0," ",VLOOKUP(B30,Accomodations!$B$7:$F$31,5,TRUE)) -> St. Christophers Inn Berlin | E30: =IF(Table2[[#This Row],[Location]]=C29," ", "Yes") -> Yes | F30: Eurorail Train | G30: Chill
B31: =B30+1 -> 44716 | C31: =VLOOKUP(B31,'Trip Dreaming'!$K$6:$M$30,3,TRUE) -> Berlin, Germany | D31: =IF(VLOOKUP(B31,Accomodations!$B$7:$F$31,5,TRUE)=0," ",VLOOKUP(B31,Accomodations!$B$7:$F$31,5,TRUE)) -> St. Christophers Inn Berlin | E31: =IF(Table2[[#This Row],[Location]]=C30," ", "Yes") | G31: Walking Tour
B32: =B31+1 -> 44717 | C32: =VLOOKUP(B32,'Trip Dreaming'!$K$6:$M$30,3,TRUE) -> Berlin, Germany | D32: =IF(VLOOKUP(B32,Accomodations!$B$7:$F$31,5,TRUE)=0," ",VLOOKUP(B32,Accomodations!$B$7:$F$31,5,TRUE)) -> St. Christophers Inn Berlin | E32: =IF(Table2[[#This Row],[Location]]=C31," ", "Yes") | G32: Clubbing
B33: =B32+1 -> 44718 | C33: =VLOOKUP(B33,'Trip Dreaming'!$K$6:$M$30,3,TRUE) -> Berlin, Germany | D33: =IF(VLOOKUP(B33,Accomodations!$B$7:$F$31,5,TRUE)=0," ",VLOOKUP(B33,Accomodations!$B$7:$F$31,5,TRUE)) -> St. Christophers Inn Berlin | E33: =IF(Table2[[#This Row],[Location]]=C32," ", "Yes") | G33: Clubbing
B34: =B33+1 -> 44719 | C34: =VLOOKUP(B34,'Trip Dreaming'!$K$6:$M$30,3,TRUE) -> Berlin, Germany | D34: =IF(VLOOKUP(B34,Accomodations!$B$7:$F$31,5,TRUE)=0," ",VLOOKUP(B34,Accomodations!$B$7:$F$31,5,TRUE)) -> St. Christophers Inn Berlin | E34: =IF(Table2[[#This Row],[Location]]=C33," ", "Yes") | G34: Concentration Camp
B35: =B34+1 -> 44720 | C35: =VLOOKUP(B35,'Trip Dreaming'!$K$6:$M$30,3,TRUE) -> Amsterdam, Netherlands | D35: =IF(VLOOKUP(B35,Accomodations!$B$7:$F$31,5,TRUE)=0," ",VLOOKUP(B35,Accomodations!$B$7:$F$31,5,TRUE)) -> Hans Brinker Hostel | E35: =IF(Table2[[#This Row],[Location]]=C34," ", "Yes") -> Yes | F35: Fly in from Berlin | G35: Chill
B36: =B35+1 -> 44721 | C36: =VLOOKUP(B36,'Trip Dreaming'!$K$6:$M$30,3,TRUE) -> Amsterdam, Netherlands | D36: =IF(VLOOKUP(B36,Accomodations!$B$7:$F$31,5,TRUE)=0," ",VLOOKUP(B36,Accomodations!$B$7:$F$31,5,TRUE)) -> Hans Brinker Hostel | E36: =IF(Table2[[#This Row],[Location]]=C35," ", "Yes") | G36: Watch friends play vb
B37: =B36+1 -> 44722 | C37: =VLOOKUP(B37,'Trip Dreaming'!$K$6:$M$30,3,TRUE) -> Amsterdam, Netherlands | D37: =IF(VLOOKUP(B37,Accomodations!$B$7:$F$31,5,TRUE)=0," ",VLOOKUP(B37,Accomodations!$B$7:$F$31,5,TRUE)) -> Hans Brinker Hostel | E37: =IF(Table2[[#This Row],[Location]]=C36," ", "Yes") | G37: Go on tours
B38: =B37+1 -> 44723 | C38: =VLOOKUP(B38,'Trip Dreaming'!$K$6:$M$30,3,TRUE) -> Amsterdam, Netherlands | D38: =IF(VLOOKUP(B38,Accomodations!$B$7:$F$31,5,TRUE)=0," ",VLOOKUP(B38,Accomodations!$B$7:$F$31,5,TRUE)) -> Hans Brinker Hostel | E38: =IF(Table2[[#This Row],[Location]]=C37," ", "Yes") | G38: canal tour
B39: =B38+1 -> 44724 | C39: =VLOOKUP(B39,'Trip Dreaming'!$K$6:$M$30,3,TRUE) -> Amsterdam, Netherlands | D39: =IF(VLOOKUP(B39,Accomodations!$B$7:$F$31,5,TRUE)=0," ",VLOOKUP(B39,Accomodations!$B$7:$F$31,5,TRUE)) -> Hans Brinker Hostel | E39: =IF(Table2[[#This Row],[Location]]=C38," ", "Yes") | G39: Watch friends play vb
B40: =B39+1 -> 44725 | C40: =VLOOKUP(B40,'Trip Dreaming'!$K$6:$M$30,3,TRUE) -> Copenhagen, Denmark | D40: =IF(VLOOKUP(B40,Accomodations!$B$7:$F$31,5,TRUE)=0," ",VLOOKUP(B40,Accomodations!$B$7:$F$31,5,TRUE)) -> Generator Copenhagen | E40: =IF(Table2[[#This Row],[Location]]=C39," ", "Yes") -> Yes | F40: Fly in From Amsterdam | G40: Chill
B41: =B40+1 -> 44726 | C41: =VLOOKUP(B41,'Trip Dreaming'!$K$6:$M$30,3,TRUE) -> Copenhagen, Denmark | D41: =IF(VLOOKUP(B41,Accomodations!$B$7:$F$31,5,TRUE)=0," ",VLOOKUP(B41,Accomodations!$B$7:$F$31,5,TRUE)) -> Generator Copenhagen | E41: =IF(Table2[[#This Row],[Location]]=C40," ", "Yes") | G41: Walking Tour
B42: =B41+1 -> 44727 | C42: =VLOOKUP(B42,'Trip Dreaming'!$K$6:$M$30,3,TRUE) -> Copenhagen, Denmark | D42: =IF(VLOOKUP(B42,Accomodations!$B$7:$F$31,5,TRUE)=0," ",VLOOKUP(B42,Accomodations!$B$7:$F$31,5,TRUE)) -> Generator Copenhagen | E42: =IF(Table2[[#This Row],[Location]]=C41," ", "Yes") | G42: go to sweden
B43: =B42+1 -> 44728 | C43: =VLOOKUP(B43,'Trip Dreaming'!$K$6:$M$30,3,TRUE) -> Copenhagen, Denmark | D43: =IF(VLOOKUP(B43,Accomodations!$B$7:$F$31,5,TRUE)=0," ",VLOOKUP(B43,Accomodations!$B$7:$F$31,5,TRUE)) -> Generator Copenhagen | E43: =IF(Table2[[#This Row],[Location]]=C42," ", "Yes") | G43: hang out
B44: =B43+1 -> 44729 | C44: =VLOOKUP(B44,'Trip Dreaming'!$K$6:$M$30,3,TRUE) -> Dublin, Ireland | D44: =IF(VLOOKUP(B44,Accomodations!$B$7:$F$31,5,TRUE)=0," ",VLOOKUP(B44,Accomodations!$B$7:$F$31,5,TRUE)) -> Abbey Court Hostel | E44: =IF(Table2[[#This Row],[Location]]=C43," ", "Yes") -> Yes | F44: Fly in from Copenhagen | G44: party
B45: =B44+1 -> 44730 | C45: =VLOOKUP(B45,'Trip Dreaming'!$K$6:$M$30,3,TRUE) -> Dublin, Ireland | D45: =IF(VLOOKUP(B45,Accomodations!$B$7:$F$31,5,TRUE)=0," ",VLOOKUP(B45,Accomodations!$B$7:$F$31,5,TRUE)) -> Abbey Court Hostel | E45: =IF(Table2[[#This Row],[Location]]=C44," ", "Yes") | G45: Party
...

Sheet Itinerary-CODE
B2: =MONTH(DreamStartDate) -> 5
B3: Sunday | C3: Monday | D3: Tuesday | E3: Wednesday | F3: Thursday | G3: Friday | H3: Saturday
A4: Month 1 | B4: {=IF(MONTH(DATE(YEAR(DreamStartDate),MONTH(DreamStartDate),1))- MONTH(DATE(YEAR(DreamStartDate),MONTH(DreamStartDate),1)- (WEEKDAY(DATE(YEAR(DreamStartDate),MONTH(DreamStartDate),1))-1)+ {0;1;2;3;4;5}*7+{1,2,3,4,5,6,7}-1),"",DATE(YEAR(DreamStartDate), MONTH(DreamStartDate),1)-(WEEKDAY(DATE(YEAR(DreamStartDate), MONTH(DreamStartDate),1))-1)+{0;1;2;3;4;5}*7+{1,2,3,4,5,6,7}-1)} -> 44682 | C4: 44683 | D4: 44684 | E4: 44685 | F4: 44686 | G4: 44687 | H4: 44688
B5: 44689 | C5: 44690 | D5: 44691 | E5: 44692 | F5: 44693 | G5: 44694 | H5: 44695
B6: 44696 | C6: 44697 | D6: 44698 | E6: 44699 | F6: 44700 | G6: 44701 | H6: 44702
B7: 44703 | C7: 44704 | D7: 44705 | E7: 44706 | F7: 44707 | G7: 44708 | H7: 44709
B8: 44710 | C8: 44711 | D8: 44712
A10: Month 2 | B10: {=IF(MONTH(DATE(YEAR(DreamStartDate),DreamStartMonth+1,1))- MONTH(DATE(YEAR(DreamStartDate),DreamStartMonth+1,1)- (WEEKDAY(DATE(YEAR(DreamStartDate),DreamStartMonth+1,1))-1)+ {0;1;2;3;4;5}*7+{1,2,3,4,5,6,7}-1),"",DATE(YEAR(DreamStartDate), DreamStartMonth+1,1)-(WEEKDAY(DATE(YEAR(DreamStartDate), DreamStartMonth+1,1))-1)+{0;1;2;3;4;5}*7+{1,2,3,4,5,6,7}-1)} | E10: 44713 | F10: 44714 | G10: 44715 | H10: 44716
B11: 44717 | C11: 44718 | D11: 44719 | E11: 44720 | F11: 44721 | G11: 44722 | H11: 44723
B12: 44724 | C12: 44725 | D12: 44726 | E12: 44727 | F12: 44728 | G12: 44729 | H12: 44730
B13: 44731 | C13: 44732 | D13: 44733 | E13: 44734 | F13: 44735 | G13: 44736 | H13: 44737
B14: 44738 | C14: 44739 | D14: 44740 | E14: 44741 | F14: 44742
A16: Month 3 | B16: {=IF(MONTH(DATE(YEAR(DreamStartDate),DreamStartMonth+2,1))- MONTH(DATE(YEAR(DreamStartDate),DreamStartMonth+2,1)- (WEEKDAY(DATE(YEAR(DreamStartDate),DreamStartMonth+2,1))-1)+ {0;1;2;3;4;5}*7+{1,2,3,4,5,6,7}-1),"",DATE(YEAR(DreamStartDate), DreamStartMonth+2,1)-(WEEKDAY(DATE(YEAR(DreamStartDate), DreamStartMonth+2,1))-1)+{0;1;2;3;4;5}*7+{1,2,3,4,5,6,7}-1)} | G16: 44743 | H16: 44744
B17: 44745 | C17: 44746 | D17: 44747 | E17: 44748 | F17: 44749 | G17: 44750 | H17: 44751
B18: 44752 | C18: 44753 | D18: 44754 | E18: 44755 | F18: 44756 | G18: 44757 | H18: 44758
B19: 44759 | C19: 44760 | D19: 44761 | E19: 44762 | F19: 44763 | G19: 44764 | H19: 44765
B20: 44766 | C20: 44767 | D20: 44768 | E20: 44769 | F20: 44770 | G20: 44771 | H20: 44772
B21: 44773

Sheet Accomodations
B2: Accomodations | F2: Total Accomodation Cost | J2: % Booked
B3: The hostels, airbnbs, tents?, boats, and other places you will be staying! | F3: =SUM(I7:I31) -> 2228 | J3: =COUNTIF(J7:J31,"Yes")/COUNTA(F7:F31) -> 1
B4: This data feeds into the itinerary!
B6: Check-In Date | C6: Check-Out Date | D6: Location | E6: # of Days | F6: Name | G6: $ Per Night | H6: $ All Nights | I6: Total Booked Cost | J6: Booked? | K6: Booking Site | L6: Cash or Card
B7: ='Trip Dreaming'!K6 -> 44694 | C7: ='Trip Dreaming'!L6 -> 44697 | D7: ='Trip Dreaming'!M6 -> Zurich, Switzerland | E7: =IF('Trip Dreaming'!N6=0," ",'Trip Dreaming'!N6) -> 3 | F7: Zurich Youth Hostel | I7: 220 | J7: Yes
B8: ='Trip Dreaming'!K7 -> 44697 | C8: ='Trip Dreaming'!L7 -> 44700 | D8: ='Trip Dreaming'!M7 -> Lucerne, Switzerland | E8: =IF('Trip Dreaming'!N7=0," ",'Trip Dreaming'!N7) -> 3 | F8: Barabas Luzern | I8: 185 | J8: Yes
B9: ='Trip Dreaming'!K8 -> 44700 | C9: ='Trip Dreaming'!L8 -> 44704 | D9: ='Trip Dreaming'!M8 -> Salzburg, Austria | E9: =IF('Trip Dreaming'!N8=0," ",'Trip Dreaming'!N8) -> 4 | F9: Chalet Hostel @ Backpackers Villa | I9: 359 | J9: Yes
B10: ='Trip Dreaming'!K9 -> 44704 | C10: ='Trip Dreaming'!L9 -> 44711 | D10: ='Trip Dreaming'!M9 -> Interlaken, Switzerland | E10: =IF('Trip Dreaming'!N9=0," ",'Trip Dreaming'!N9) -> 7 | F10: YoHo - Internationall Youth Hostel | I10: 139 | J10: Yes
B11: ='Trip Dreaming'!K10 -> 44711 | C11: ='Trip Dreaming'!L10 -> 44712 | D11: ='Trip Dreaming'!M10 -> Halstatt, Austria | E11: =IF('Trip Dreaming'!N10=0," ",'Trip Dreaming'!N10) -> 1 | F11: Pension Leopoldine | I11: 91 | J11: Yes
B12: ='Trip Dreaming'!K11 -> 44712 | C12: ='Trip Dreaming'!L11 -> 44715 | D12: ='Trip Dreaming'!M11 -> Munich, Germany | E12: =IF('Trip Dreaming'!N11=0," ",'Trip Dreaming'!N11) -> 3 | F12: Wombat's City Hostel Munich | I12: 124 | J12: Yes
B13: ='Trip Dreaming'!K12 -> 44715 | C13: ='Trip Dreaming'!L12 -> 44720 | D13: ='Trip Dreaming'!M12 -> Berlin, Germany | E13: =IF('Trip Dreaming'!N12=0," ",'Trip Dreaming'!N12) -> 5 | F13: St. Christophers Inn Berlin | I13: 256 | J13: Yes
B14: ='Trip Dreaming'!K13 -> 44720 | C14: ='Trip Dreaming'!L13 -> 44725 | D14: ='Trip Dreaming'!M13 -> Amsterdam, Netherlands | E14: =IF('Trip Dreaming'!N13=0," ",'Trip Dreaming'!N13) -> 5 | F14: Hans Brinker Hostel | I14: 138 | J14: Yes
B15: ='Trip Dreaming'!K14 -> 44725 | C15: ='Trip Dreaming'!L14 -> 44729 | D15: ='Trip Dreaming'!M14 -> Copenhagen, Denmark | E15: =IF('Trip Dreaming'!N14=0," ",'Trip Dreaming'!N14) -> 4 | F15: Generator Copenhagen | I15: 175 | J15: Yes
B16: ='Trip Dreaming'!K15 -> 44729 | C16: ='Trip Dreaming'!L15 -> 44735 | D16: ='Trip Dreaming'!M15 -> Dublin, Ireland | E16: =IF('Trip Dreaming'!N15=0," ",'Trip Dreaming'!N15) -> 6 | F16: Abbey Court Hostel | I16: 182 | J16: Yes
B17: ='Trip Dreaming'!K16 -> 44735 | C17: ='Trip Dreaming'!L16 -> 44740 | D17: ='Trip Dreaming'!M16 -> Edinburgh, Scotland | E17: =IF('Trip Dreaming'!N16=0," ",'Trip Dreaming'!N16) -> 5 | F17: Kick Ass Greyfriars | I17: 125 | J17: Yes
B18: ='Trip Dreaming'!K17 -> 44740 | C18: ='Trip Dreaming'!L17 -> 44747 | D18: ='Trip Dreaming'!M17 -> London, England | E18: =IF('Trip Dreaming'!N17=0," ",'Trip Dreaming'!N17) -> 7 | F18: PubLove @ The White Ferry | I18: 234 | J18: Yes
B19: ='Trip Dreaming'!K18 -> 44747 | C19: ='Trip Dreaming'!L18 -> 44747 | D19: ='Trip Dreaming'!M18 | E19: =IF('Trip Dreaming'!N18=0," ",'Trip Dreaming'!N18)
B20: ='Trip Dreaming'!K19 | C20: ='Trip Dreaming'!L19 | D20: ='Trip Dreaming'!M19 | E20: =IF('Trip Dreaming'!N19=0," ",'Trip Dreaming'!N19)
B21: ='Trip Dreaming'!K20 | C21: ='Trip Dreaming'!L20 | D21: ='Trip Dreaming'!M20 | E21: =IF('Trip Dreaming'!N20=0," ",'Trip Dreaming'!N20)
B22: ='Trip Dreaming'!K21 | C22: ='Trip Dreaming'!L21 | D22: ='Trip Dreaming'!M21 | E22: =IF('Trip Dreaming'!N21=0," ",'Trip Dreaming'!N21)
B23: ='Trip Dreaming'!K22 | C23: ='Trip Dreaming'!L22 | D23: ='Trip Dreaming'!M22 | E23: =IF('Trip Dreaming'!N22=0," ",'Trip Dreaming'!N22)
B24: ='Trip Dreaming'!K23 | C24: ='Trip Dreaming'!L23 | D24: ='Trip Dreaming'!M23 | E24: =IF('Trip Dreaming'!N23=0," ",'Trip Dreaming'!N23)
B25: ='Trip Dreaming'!K24 | C25: ='Trip Dreaming'!L24 | D25: ='Trip Dreaming'!M24 | E25: =IF('Trip Dreaming'!N24=0," ",'Trip Dreaming'!N24)
B26: ='Trip Dreaming'!K25 | C26: ='Trip Dreaming'!L25 | D26: ='Trip Dreaming'!M25 | E26: =IF('Trip Dreaming'!N25=0," ",'Trip Dreaming'!N25)
B27: ='Trip Dreaming'!K26 | C27: ='Trip Dreaming'!L26 | D27: ='Trip Dreaming'!M26 | E27: =IF('Trip Dreaming'!N26=0," ",'Trip Dreaming'!N26)
B28: ='Trip Dreaming'!K27 | C28: ='Trip Dreaming'!L27 | D28: ='Trip Dreaming'!M27 | E28: =IF('Trip Dreaming'!N27=0," ",'Trip Dreaming'!N27)
B29: ='Trip Dreaming'!K28 | C29: ='Trip Dreaming'!L28 | D29: ='Trip Dreaming'!M28 | E29: =IF('Trip Dreaming'!N28=0," ",'Trip Dreaming'!N28)
B30: ='Trip Dreaming'!K29 | C30: ='Trip Dreaming'!L29 | D30: ='Trip Dreaming'!M29 | E30: =IF('Trip Dreaming'!N29=0," ",'Trip Dreaming'!N29)
B31: ='Trip Dreaming'!K30 | C31: ='Trip Dreaming'!L30 | D31: ='Trip Dreaming'!M30 | E31: =IF('Trip Dreaming'!N30=0," ",'Trip Dreaming'!N30)

Sheet Transportation
B2: Transportation | H2: Total Transportation Cost
B3: What days you are traveling and how! This data doesn’t go anywhere it's just for organization. | H3: =SUM(G7:G32) -> 910
B6: Date | C6: From | D6: To | E6: Via | F6: Carrier | G6: Cost $$$ | H6: Roundtrip/Oneway/Unlimited | I6: Reservation # | J6: Confirmation #
B7: 44693 | C7: DFW | D7: Zurich | E7: Flight | F7: AA | G7: 110 | H7: Oneway
B8: 44747 | C8: London Heathrow | D8: DFW | G8: 300 | H8: Oneway
B9: Any Day | C9: EuroRail Pass | G9: 500 | H9: Unlimited

Sheet Budget
B2: Trip Budget
B3: Here you can set your budget for spending and see how well you are following your budget
C6: Total Spending Limit
C7: what is your DREEEEEAM budget?
C8: this is your current total budget | G8: =SUM(H10,H12,F14,I17,J19,H21) -> 7238
C9: Travel
C10: flights, trains, passes, bus tickets, rental cars. | H10: 1500 | O10: Budget to Live by
C11: Accomodations | O11: Travel | P11: =H10/G8 -> 0.20723957
C12: hostels, hotel rooms, airbnbs, house boats | H12: =Accomodations!F3 -> 2228 | O12: Accomodation | P12: =H12/G8 -> 0.30781984
C13: Food | O13: Food | P13: =F15/G8 -> 0.073224648
C14: daily food budget | F14: 10 | O14: Activities | P14: =I17/G8 -> 0.20723957
C15: food budget for the whole trip | F15: =F14*'Trip Dreaming'!L3 -> 530 | O15: Spending Money | P15: =J19/G8 -> 0.13815971
C16: Activities | O16: Safety Money | P16: =H21/G8 -> 0.13815971
C17: tours, skydiving, entry fees, museums, cooking classes | I17: 1500
C18: Spending Money
C19: extra cash to have on hand to purchase whatever your heart desires | J19: 1000
C20: Safety Money
C21: backup cash to get a flight home / hospital bills | H21: 1000

Sheet Building a Budget
B2: Trip Budget - I already have something in mind… | M2: Trip Budget - I have no clue…
B3: You already know how much you plan on spending for these categories | M3: You need a little help coming up with a budget for your trip
B5: Total Spending Limit | M5: Total Spending Limit
B6: this is the sum of the categories below. | I6: =SUM(I8,I10,I13,I15,I17,I19) -> 1500 | M6: this is the abslute max you can spend. | T6: 5000
B7: Travel | M7: Travel
B8: flights, trains, passes, bus tickets, rental cars. | I8: 1500 | M8: flights, trains, passes, bus tickets, rental cars. | T8: =SUM(Transportation!H3) -> 910
B9: Accomodations | M9: Accomodations
B10: hostels, hotel rooms, airbnbs, house boats | M10: hostels, hotel rooms, airbnbs, house boats | T10: =Accomodations!F3 -> 2228
B11: Food | M11: Food
B12: daily food budget | M12: daily food budget | T12: 10
B13: food budget for the whole trip | M13: food budget for the whole trip | T13: =T12*'Trip Dreaming'!L3 -> 530
B14: Activities | M14: Activities
B15: tours, skydiving, entry fees, museums, cooking classes | M15: tours, skydiving, entry fees, museums, cooking classes
B16: Spending Money | M16: Spending Money
B17: extra cash to have on hand to purchase whatever your heart desires | M17: extra cash to have on hand to purchase whatever your heart desires
B18: Safety Money | M18: Safety Money
B19: backup cash to get a flight home / hospital bills | M19: backup cash to get a flight home / hospital bills
N23: This is what is left in the budget: | Q23: =T6-SUM(T8,T10,T13,T15,T17,T19) -> 1332

Sheet Packing List
B2: Packing List & Checklist | F2: Undies | J2: Miscellaneous
B3: Keep track of everything you plan on bringing | F3: Item | G3: Qty | J3: Item | K3: Qty
F4: Calvin Klien bralette | G4: 3 | J4: 55L backpack | K4: 1
B5: Clothes | F5: Panties | G5: 16 | J5: Packing cubes | K5: 6
B6: Item | C6: Qty | F6: Sports bra | G6: 3 | J6: Miniature gorilla tripod | K6: 1
B7: Levi's jeans (black & denim) | C7: 2 | F7: Regular socks | G7: 4 | J7: microfiber towel | K7: 1
B8: Jean shorts | C8: 1 | F8: Hiking socks | G8: 2 | J8: toothbrush for dirty shoes | K8: 1
B9: Black polka dot skirt | C9: 1 | J9: dirty clothes bag | K9: 1
B10: Blazers (leather & check) | C10: 2 | J10: dirty shoes back | K10: 1
B11: Down jacket | C11: 1 | J11: laundry detergent | K11: 1
B12: graphic tee | C12: 2 | J12: fanny pack | K12: 1
B13: high neck bramis (black, grey, & pink) | C13: 3 | F13: Technology | J13: tote bag | K13: 1
B14: tank top (navy & black) | C14: 2 | F14: Item | G14: Qty
B15: going out tops | C15: 3 | F15: Phone charger | G15: 1
B16: black turtleneck | C16: 1 | F16: Laptop & charger | G16: 1
B17: black romper | C17: 1 | F17: Portable charger | G17: 2
B18: black maxi dress | C18: 1 | F18: Power outlet adapter (EU & UK) | G18: 2 | J18: Toiletries & Medications
B19: Black running shorts | C19: 1 | F19: Bluetooth camera button | G19: 1 | J19: Item | K19: Qty
B20: Navy biker shorts | C20: 1 | F20: airpods | G20: 1 | J20: shampoo | K20: 1
B21: longsleeve running shirt | C21: 1 | F21: digital camera & charger | G21: 1 | J21: conditioner | K21: 2
B22: shortsleeve running shirt | C22: 1 | J22: leave in conditioner | K22: 1
B23: rain jacket | J23: face wash | K23: 1
J24: moisturizer | K24: 1
J25: sunscreen | K25: 1
J26: bar of soap | K26: 1
F27: Shoes | J27: toothbrush | K27: 1
F28: Item | G28: Qty | J28: toothpaste | K28: 1
F29: Veja sneakers | G29: 1 | J29: nausea medicine
F30: Waterproof birkenstocks | G30: 1 | J30: sleep aid
F31: Hiking shoes | G31: 1 | J31: advil

Sheet Plan Checklist
